Workbook

Sheet DataSekolah dan Kecamatan
C1: Data Nama Sekolah, Alokasi dana BOS dan Sarpas dan Kumlah Siswa Per-Kecamatan
C3: No | D3: Arjawinangun | I3: Astanajapura | N3: Babakan | S3: Beber | X3: Ciledug | AC3: Ciwaringin | AH3: Depok | AM3: Dukupuntang | AR3: Gebang | AW3: Gegesik | BB3: Gempol | BG3: Greged | BL3: Gunungjati | BQ3: Jamblang | BV3: Kaliwedi | CA3: Kapetakan | CF3: Karangsembung | CK3: Karangwareng | CP3: Kedawung | CU3: Klangenan | CZ3: Lemahabang | DE3: Losari | DJ3: Mundu | DO3: Pabedilan | DT3: Pabuaran | DY3: Palimanan | ED3: Pangenan | EI3: Panguragan | EN3: Pasaleman | ES3: Plered | EX3: Plumbon | FC3: Sedong | FH3: Sumber | FM3: Suranenggala | FR3: Susukan | FW3: Susukan Lebak | GB3: Talun | GG3: Tengahtani | GL3: Waled | GQ3: Weru
D4: NPSN | E4: Nama Sekolah | F4: Pagu | G4: Jumlah Siswa | H4: Dana Sarpas | I4: NPSN | J4: Nama Sekolah | K4: Pagu | L4: Jumlah Siswa | M4: Dana Sarpas | N4: NPSN | O4: Nama Sekolah | P4: Pagu | Q4: Jumlah Siswa | R4: Dana Sarpas | S4: NPSN | T4: Nama Sekolah | U4: Pagu | V4: Jumlah Siswa | W4: Dana Sarpas | X4: NPSN | Y4: Nama Sekolah | Z4: Pagu | AA4: Jumlah Siswa | AB4: Dana Sarpas | AC4: NPSN | AD4: Nama Sekolah | AE4: Pagu | AF4: Jumlah Siswa | AG4: Dana Sarpas | AH4: NPSN | AI4: Nama Sekolah | AJ4: Pagu | AK4: Jumlah Siswa | AL4: Dana Sarpas | AM4: NPSN | AN4: Nama Sekolah | AO4: Pagu | AP4: Jumlah Siswa | AQ4: Dana Sarpas | AR4: NPSN | AS4: Nama Sekolah | AT4: Pagu | AU4: Jumlah Siswa | AV4: Dana Sarpas | AW4: NPSN | AX4: Nama Sekolah | AY4: Pagu | AZ4: Jumlah Siswa | BA4: Dana Sarpas | BB4: NPSN | BC4: Nama Sekolah | BD4: Pagu | BE4: Jumlah Siswa | BF4: Dana Sarpas | BG4: NPSN | BH4: Nama Sekolah | BI4: Pagu | BJ4: Jumlah Siswa | BK4: Dana Sarpas | BL4: NPSN | BM4: Nama Sekolah | BN4: Pagu | BO4: Jumlah Siswa | BP4: Dana Sarpas | BQ4: NPSN | BR4: Nama Sekolah | BS4: Pagu | BT4: Jumlah Siswa | BU4: Dana Sarpas | BV4: NPSN | BW4: Nama Sekolah | BX4: Pagu | BY4: Jumlah Siswa | BZ4: Dana Sarpas | CA4: NPSN | CB4: Nama Sekolah | CC4: Pagu | CD4: Jumlah Siswa | CE4: Dana Sarpas | CF4: NPSN | CG4: Nama Sekolah | CH4: Pagu | CI4: Jumlah Siswa | CJ4: Dana Sarpas | CK4: NPSN | CL4: Nama Sekolah | CM4: Pagu | CN4: Jumlah Siswa | CO4: Dana Sarpas | CP4: NPSN | CQ4: Nama Sekolah | CR4: Pagu | CS4: Jumlah Siswa | CT4: Dana Sarpas | CU4: NPSN | CV4: Nama Sekolah | CW4: Pagu | CX4: Jumlah Siswa | CY4: Dana Sarpas | CZ4: NPSN | DA4: Nama Sekolah | DB4: Pagu | DC4: Jumlah Siswa | DD4: Dana Sarpas | DE4: NPSN | DF4: Nama Sekolah | DG4: Pagu | DH4: Jumlah Siswa | DI4: Dana Sarpas | DJ4: NPSN | DK4: Nama Sekolah | DL4: Pagu | DM4: Jumlah Siswa | DN4: Dana Sarpas | DO4: NPSN | DP4: Nama Sekolah | DQ4: Pagu | DR4: Jumlah Siswa | DS4: Dana Sarpas | DT4: NPSN | DU4: Nama Sekolah | DV4: Pagu | DW4: Jumlah Siswa | DX4: Dana Sarpas | DY4: NPSN | DZ4: Nama Sekolah | EA4: Pagu | EB4: Jumlah Siswa | EC4: Dana Sarpas | ED4: NPSN | EE4: Nama Sekolah | EF4: Pagu | EG4: Jumlah Siswa | EH4: Dana Sarpas | EI4: NPSN | EJ4: Nama Sekolah | EK4: Pagu | EL4: Jumlah Siswa | EM4: Dana Sarpas | EN4: NPSN | EO4: Nama Sekolah | EP4: Pagu | EQ4: Jumlah Siswa | ER4: Dana Sarpas | ES4: NPSN | ET4: Nama Sekolah | EU4: Pagu | EV4: Jumlah Siswa | EW4: Dana Sarpas | EX4: NPSN | EY4: Nama Sekolah | EZ4: Pagu | FA4: Jumlah Siswa | FB4: Dana Sarpas | FC4: NPSN | FD4: Nama Sekolah | FE4: Pagu | FF4: Jumlah Siswa | FG4: Dana Sarpas | FH4: NPSN | FI4: Nama Sekolah | FJ4: Pagu | FK4: Jumlah Siswa | FL4: Dana Sarpas | FM4: NPSN | FN4: Nama Sekolah | FO4: Pagu | FP4: Jumlah Siswa | FQ4: Dana Sarpas | FR4: NPSN | FS4: Nama Sekolah | FT4: Pagu | FU4: Jumlah Siswa | FV4: Dana Sarpas | FW4: NPSN | FX4: Nama Sekolah | FY4: Pagu | FZ4: Jumlah Siswa | GA4: Dana Sarpas | GB4: NPSN | GC4: Nama Sekolah | GD4: Pagu | GE4: Jumlah Siswa | GF4: Dana Sarpas | GG4: NPSN | GH4: Nama Sekolah | GI4: Pagu | GJ4: Jumlah Siswa | GK4: Dana Sarpas | GL4: NPSN | GM4: Nama Sekolah | GN4: Pagu | GO4: Jumlah Siswa | GP4: Dana Sarpas | GQ4: NPSN | GR4: Nama Sekolah | GS4: Pagu | GT4: Jumlah Siswa | GU4: Dana Sarpas
C5: 1 | D5: 20215393 | E5: SD NEGERI 2 KARANGSAMBUNG | F5: 79120000 | G5: =F5/920000 -> 86 | H5: =F5*20% -> 15824000 | I5: 20215439 | J5: SD NEGERI 2 KANCI | K5: 83720000 | L5: =K5/920000 -> 91 | M5: =K5*20% -> 16744000 | N5: 20215192 | O5: SD NEGERI 1 CANGKUANG | P5: 268640000 | Q5: =P5/920000 -> 292 | R5: =P5*20% -> 53728000 | S5: 20215335 | T5: SD NEGERI 2 HALIMPU | U5: 237360000 | V5: =U5/920000 -> 258 | W5: =U5*20% -> 47472000 | X5: 20215294 | Y5: SD NEGERI 1 CILEDUGTENGAH | Z5: 284280000 | AA5: =Z5/920000 -> 309 | AB5: =Z5*20% -> 56856000 | AC5: 20215261 | AD5: SD NEGERI 1 GINTUNG TENGAH | AE5: 204240000 | AF5: =AE5/920000 -> 222 | AG5: =AE5*20% -> 40848000 | AH5: 20215061 | AI5: SD NEGERI 4 KASUGENGAN LOR | AJ5: 90160000 | AK5: =AJ5/920000 -> 98 | AL5: =AJ5*20% -> 18032000 | AM5: 20215209 | AN5: SD NEGERI 1 BOBOS | AO5: 63480000 | AP5: =AO5/920000 -> 69 | AQ5: =AO5*20% -> 12696000 | AR5: 20214475 | AS5: SD NEGERI 3 GEBANG KULON | AT5: 159160000 | AU5: =AT5/920000 -> 173 | AV5: =AT5*20% -> 31832000 | AW5: 20270536 | AX5: SDN 2 Slendra | AY5: 111320000 | AZ5: =AY5/920000 -> 121 | BA5: =AY5*20% -> 22264000 | BB5: 20215572 | BC5: SD NEGERI 1 WALAHAR | BD5: 241040000 | BE5: =BD5/920000 -> 262 | BF5: =BD5*20% -> 48208000 | BG5: 20215050 | BH5: SD NEGERI 1 KAMARANG | BI5: 239200000 | BJ5: =BI5/920000 -> 260 | BK5: =BI5*20% -> 47840000 | BL5: 20215177 | BM5: SD NEGERI 1 BUYUT | BN5: 160080000 | BO5: =BN5/920000 -> 174 | BP5: =BN5*20% -> 32016000 | BQ5: 20215530 | BR5: SD NEGERI 2 BAKUNGKIDUL | BS5: 110400000 | BT5: =BS5/920000 -> 120 | BU5: =BS5*20% -> 22080000 | BV5: 20215070 | BW5: SD NEGERI 1 KALIWEDI KIDUL | BX5: 122360000 | BY5: =BX5/920000 -> 133 | BZ5: =BX5*20% -> 24472000 | CA5: 20215545 | CB5: SD NEGERI 2 BUNGKO | CC5: 166520000 | CD5: =CC5/920000 -> 181 | CE5: =CC5*20% -> 33304000 | CF5: 20215391 | CG5: SD NEGERI 2 KARANGSEMBUNG | CH5: 129720000 | CI5: =CH5/920000 -> 141 | CJ5: =CH5*20% -> 25944000 | CK5: 20214659 | CL5: SD NEGERI 2 KUBANGDELEG | CM5: 111320000 | CN5: =CM5/920000 -> 121 | CO5: =CM5*20% -> 22264000 | CP5: 20214665 | CQ5: SD NEGERI 2 KERTAWINANGUN | CR5: 138920000 | CS5: =CR5/920000 -> 151 | CT5: =CR5*20% -> 27784000 | CU5: 20215526 | CV5: SD NEGERI 2 BANGODUA | CW5: 207920000 | CX5: =CW5/920000 -> 226 | CY5: =CW5*20% -> 41584000 | CZ5: 20215164 | DA5: SD NEGERI 1 LEUWIDINGDING | DB5: 180320000 | DC5: =DB5/920000 -> 196 | DD5: =DB5*20% -> 36064000 | DE5: 20215472 | DF5: SD NEGERI 1 TAWANGSARI | DG5: 221720000 | DH5: =DG5/920000 -> 241 | DI5: =DG5*20% -> 44344000 | DJ5: 20215457 | DK5: UPTD SD NEGERI 1 SUCI | DL5: 602600000 | DM5: =DL5/920000 -> 655 | DN5: =DL5*20% -> 120520000 | DO5: 20214632 | DP5: SD NEGERI 2 PABEDILAN KALER | DQ5: 103040000 | DR5: =DQ5/920000 -> 112 | DS5: =DQ5*20% -> 20608000 | DT5: 20214628 | DU5: SD NEGERI 2 PABUARAN LOR | DV5: 141680000 | DW5: =DV5/920000 -> 154 | DX5: =DV5*20% -> 28336000 | DY5: 20215503 | DZ5: SD NEGERI 1 PANONGAN | EA5: 321080000 | EB5: =EA5/920000 -> 349 | EC5: =EA5*20% -> 64216000 | ED5: 20215431 | EE5: SD NEGERI 2 JAPURA LOR | EF5: 65320000 | EG5: =EF5/920000 -> 71 | EH5: =EF5*20% -> 13064000 | EI5: 20214542 | EJ5: SD NEGERI 3 PANGURAGAN KULON | EK5: 261280000 | EL5: =EK5/920000 -> 284 | EM5: =EK5*20% -> 52256000 | EN5: 20215579 | EO5: UPTD SD NEGERI 1 TONJONG | EP5: 270480000 | EQ5: =EP5/920000 -> 294 | ER5: =EP5*20% -> 54096000 | ES5: 20215001 | ET5: SD NEGERI 1 WOTGALI | EU5: 266800000 | EV5: =EU5/920000 -> 290 | EW5: =EU5*20% -> 53360000 | EX5: 20244359 | EY5: SD NEGERI 1 KARANGASEM | EZ5: 94760000 | FA5: =EZ5/920000 -> 103 | FB5: =EZ5*20% -> 18952000 | FC5: 20215127 | FD5: SD NEGERI 1 PANAMBANGAN | FE5: 160080000 | FF5: =FE5/920000 -> 174 | FG5: =FE5*20% -> 32016000 | FH5: 20214904 | FI5: SD NEGERI 5 SUMBER | FJ5: 117760000 | FK5: =FJ5/920000 -> 128 | FL5: =FJ5*20% -> 23552000 | FM5: 20214945 | FN5: SD NEGERI 3 SURANENGGALA KIDUL | FO5: 207000000 | FP5: =FO5/920000 -> 225 | FQ5: =FO5*20% -> 41400000 | FR5: 20214509 | FS5: SD NEGERI 2 WIYONG | FT5: 139840000 | FU5: =FT5/920000 -> 152 | FV5: =FT5*20% -> 27968000 | FW5: 20215477 | FX5: SD NEGERI 1 SUSUKANTONGGOH | FY5: 135240000 | FZ5: =FY5/920000 -> 147 | GA5: =FY5*20% -> 27048000 | GB5: 20215288 | GC5: SD NEGERI 1 CIPERNA | GD5: 162840000 | GE5: =GD5/920000 -> 177 | GF5: =GD5*20% -> 32568000 | GG5: 20215071 | GH5: SD NEGERI 1 KALITENGAH | GI5: 311880000 | GJ5: =GI5/920000 -> 339 | GK5: =GI5*20% -> 62376000 | GL5: 20244383 | GM5: SD NEGERI 1 WALEDKOTA | GN5: 92920000 | GO5: =GN5/920000 -> 101 | GP5: =GN5*20% -> 18584000 | GQ5: 20214752 | GR5: SD NEGERI 2 SETU KULON | GS5: 428720000 | GT5: =GS5/920000 -> 466 | GU5: =GS5*20% -> 85744000
C6: 2 | D6: 20214903 | E6: SDN 6 ARJAWINANGUN | F6: 236440000 | G6: =F6/920000 -> 257 | H6: =F6*20% -> 47288000 | I6: 20215047 | J6: SD NEGERI 1 KANCIKULON | K6: 252080000 | L6: =K6/920000 -> 274 | M6: =K6*20% -> 50416000 | N6: 20215065 | O6: SD NEGERI 1 KARANGWANGUN | P6: 138920000 | Q6: =P6/920000 -> 151 | R6: =P6*20% -> 27784000 | S6: 20215232 | T6: SD NEGERI 1 BEBER | U6: 299000000 | V6: =U6/920000 -> 325 | W6: =U6*20% -> 59800000 | X6: 20215186 | Y6: SD NEGERI 1 BOJONG NEGARA | Z6: 97520000 | AA6: =Z6/920000 -> 106 | AB6: =Z6*20% -> 19504000 | AC6: 20215547 | AD6: SD NEGERI 2 BRINGIN | AE6: 165600000 | AF6: =AE6/920000 -> 180 | AG6: =AE6*20% -> 33120000 | AH6: 20215073 | AI6: SD NEGERI 1 KEJUDEN | AJ6: 225400000 | AK6: =AJ6/920000 -> 245 | AL6: =AJ6*20% -> 45080000 | AM6: 20215379 | AN6: SD NEGERI 2 CISAAT | AO6: 181240000 | AP6: =AO6/920000 -> 197 | AQ6: =AO6*20% -> 36248000 | AR6: 20215307 | AS6: SD NEGERI 1 DOMPYONG KULON | AT6: 161000000 | AU6: =AT6/920000 -> 175 | AV6: =AT6*20% -> 32200000 | AW6: 20244356 | AX6: SD NEGERI 1 JAGAPURA KULON | AY6: 256680000 | AZ6: =AY6/920000 -> 279 | BA6: =AY6*20% -> 51336000 | BB6: 20214926 | BC6: SD NEGERI 1 CUPANG | BD6: 249320000 | BE6: =BD6/920000 -> 271 | BF6: =BD6*20% -> 49864000 | BG6: 20214657 | BH6: SD NEGERI 2 LEBAK MEKAR | BI6: 535440000 | BJ6: =BI6/920000 -> 582 | BK6: =BI6*20% -> 107088000 | BL6: 20214729 | BM6: SD NEGERI 2 SAMBENG | BN6: 84640000 | BO6: =BN6/920000 -> 92 | BP6: =BN6*20% -> 16928000 | BQ6: 20215461 | BR6: SD NEGERI 1 SITIWINANGUN | BS6: 188600000 | BT6: =BS6/920000 -> 205 | BU6: =BS6*20% -> 37720000 | BV6: 20215336 | BW6: SD NEGERI 2 GUWA LOR | BX6: 167440000 | BY6: =BX6/920000 -> 182 | BZ6: =BX6*20% -> 33488000 | CA6: 20215437 | CB6: SD NEGERI 2 KAPETAKAN | CC6: 162840000 | CD6: =CC6/920000 -> 177 | CE6: =CC6*20% -> 32568000 | CF6: 20215396 | CG6: SD NEGERI 2 KARANGMEKAR | CH6: 129720000 | CI6: =CH6/920000 -> 141 | CJ6: =CH6*20% -> 25944000 | CK6: 20215229 | CL6: SD NEGERI 1 BLENDER | CM6: 181240000 | CN6: =CM6/920000 -> 197 | CO6: =CM6*20% -> 36248000 | CP6: 20215576 | CQ6: SD NEGERI 1 TUK | CR6: 440680000 | CS6: =CR6/920000 -> 479 | CT6: =CR6*20% -> 88136000 | CU6: 20214469 | CV6: SD NEGERI 3 DANAWINANGUN | CW6: 187680000 | CX6: =CW6/920000 -> 204 | CY6: =CW6*20% -> 37536000 | CZ6: 20215517 | DA6: SD NEGERI 1 SARAJAYA | DB6: 129720000 | DC6: =DB6/920000 -> 141 | DD6: =DB6*20% -> 25944000 | DE6: 20214689 | DF6: SD NEGERI 2 TAWANGSARI | DG6: 207000000 | DH6: =DG6/920000 -> 225 | DI6: =DG6*20% -> 41400000 | DJ6: 20215008 | DK6: SD NEGERI 1 SINARANCANG | DL6: 198720000 | DM6: =DL6/920000 -> 216 | DN6: =DL6*20% -> 39744000 | DO6: 20244382 | DP6: UPTD D NEGERI 1 TERSANA | DQ6: 517040000 | DR6: =DQ6/920000 -> 562 | DS6: =DQ6*20% -> 103408000 | DT6: 20214548 | DU6: SD NEGERI 3 PABUARAN LOR | DV6: 108560000 | DW6: =DV6/920000 -> 118 | DX6: =DV6*20% -> 21712000 | DY6: 20215501 | DZ6: SD NEGERI 1 PEGAGAN | EA6: 365240000 | EB6: =EA6/920000 -> 397 | EC6: =EA6*20% -> 73048000 | ED6: 20215228 | EE6: SD NEGERI 1 BERINGIN | EF6: 196880000 | EG6: =EF6/920000 -> 214 | EH6: =EF6*20% -> 39376000 | EI6: 20215521 | EJ6: UPTD SD NEGERI 1 PANGURAGAN WETAN | EK6: 533600000 | EL6: =EK6/920000 -> 580 | EM6: =EK6*20% -> 106720000 | EN6: 20215200 | EO6: SD NEGERI 1 CIGOBANG | EP6: 194120000 | EQ6: =EP6/920000 -> 211 | ER6: =EP6*20% -> 38824000 | ES6: 20214727 | ET6: SD NEGERI 2 SARABAU | EU6: 258520000 | EV6: =EU6/920000 -> 281 | EW6: =EU6*20% -> 51704000 | EX6: 20214622 | EY6: SD NEGERI 2 PAMIJAHAN | EZ6: 131560000 | FA6: =EZ6/920000 -> 143 | FB6: =EZ6*20% -> 26312000 | FC6: 20214575 | FD6: SD NEGERI 3 SEDONG LOR | FE6: 117760000 | FF6: =FE6/920000 -> 128 | FG6: =FE6*20% -> 23552000 | FH6: 20214614 | FI6: SD NEGERI 3 KENANGA | FJ6: 246560000 | FK6: =FJ6/920000 -> 268 | FL6: =FJ6*20% -> 49312000 | FM6: 20215483 | FN6: SD NEGERI 1 SURANENGGALA KIDUL | FO6: 369840000 | FP6: =FO6/920000 -> 402 | FQ6: =FO6*20% -> 73968000 | FR6: 20215058 | FS6: SD NEGERI 1 KEDONGDONG | FT6: 336720000 | FU6: =FT6/920000 -> 366 | FV6: =FT6*20% -> 67344000 | FW6: 20215478 | FX6: SD NEGERI 1 SUSUKAN LEBAK | FY6: 91080000 | FZ6: =FY6/920000 -> 99 | GA6: =FY6*20% -> 18216000 | GB6: 20215366 | GC6: SD NEGERI 2 CIPERNA | GD6: 235520000 | GE6: =GD6/920000 -> 256 | GF6: =GD6*20% -> 47104000 | GG6: 69725666 | GH6: SD NEGERI 1 Kalibaru | GI6: 117760000 | GJ6: =GI6/920000 -> 128 | GK6: =GI6*20% -> 23552000 | GL6: 20214935 | GM6: SD NEGERI 3 WALEDKOTA | GN6: 141680000 | GO6: =GN6/920000 -> 154 | GP6: =GN6*20% -> 28336000 | GQ6: 20214940 | GR6: SD NEGERI 3 TEGALWANGI | GS6: 210680000 | GT6: =GS6/920000 -> 229 | GU6: =GS6*20% -> 42136000
C7: 3 | D7: 20215217 | E7: SD NEGERI 1 ARJAWINANGUN | F7: 490360000 | G7: =F7/920000 -> 533 | H7: =F7*20% -> 98072000 | I7: 20215432 | J7: SD NEGERI 2 JAPURA KIDUL | K7: 116840000 | L7: =K7/920000 -> 127 | M7: =K7*20% -> 23368000 | N7: 20215210 | O7: SD NEGERI 1 BABAKANGEBANG | P7: 403880000 | Q7: =P7/920000 -> 439 | R7: =P7*20% -> 80776000 | S7: 20215197 | T7: SD NEGERI 1 CIKANCAS | U7: 165600000 | V7: =U7/920000 -> 180 | W7: =U7*20% -> 33120000 | X7: 20215312 | Y7: SD NEGERI 1 CILEDUG LOR | Z7: 128800000 | AA7: =Z7/920000 -> 140 | AB7: =Z7*20% -> 25760000 | AC7: 20215211 | AD7: SD NEGERI 1 BABAKAN | AE7: 414000000 | AF7: =AE7/920000 -> 450 | AG7: =AE7*20% -> 82800000 | AH7: 20214518 | AI7: SD NEGERI 2 WARUJAYA | AJ7: 170200000 | AK7: =AJ7/920000 -> 185 | AL7: =AJ7*20% -> 34040000 | AM7: 20215344 | AN7: SD NEGERI 2 GIRINATA | AO7: 161000000 | AP7: =AO7/920000 -> 175 | AQ7: =AO7*20% -> 32200000 | AR7: 20215259 | AS7: SD NEGERI 1 GEBANGUDIK | AT7: 187680000 | AU7: =AT7/920000 -> 204 | AV7: =AT7*20% -> 37536000 | AW7: 20215265 | AX7: SD NEGERI 1 JAGAPURA LOR | AY7: 234600000 | AZ7: =AY7/920000 -> 255 | BA7: =AY7*20% -> 46920000 | BB7: 20214710 | BC7: SD NEGERI 2 WALAHAR | BD7: 157320000 | BE7: =BD7/920000 -> 171 | BF7: =BD7*20% -> 31464000 | BG7: 20215121 | BH7: SD NEGERI 1 NANGGELA | BI7: 629280000 | BJ7: =BI7/920000 -> 684 | BK7: =BI7*20% -> 125856000 | BL7: 20215487 | BM7: SD NEGERI 1 SIRNABAYA | BN7: 154560000 | BO7: =BN7/920000 -> 168 | BP7: =BN7*20% -> 30912000 | BQ7: 20214557 | BR7: SD NEGERI 3 SITIWINANGUN | BS7: 116840000 | BT7: =BS7/920000 -> 127 | BU7: =BS7*20% -> 23368000 | BV7: 20215419 | BW7: SD NEGERI 2 KALIDERES | BX7: 96600000 | BY7: =BX7/920000 -> 105 | BZ7: =BX7*20% -> 19320000 | CA7: 20215179 | CB7: SD NEGERI 1 BUNGKO LOR | CC7: 109480000 | CD7: =CC7/920000 -> 119 | CE7: =CC7*20% -> 21896000 | CF7: 20215099 | CG7: SD NEGERI 1 KALIMEANG | CH7: 110400000 | CI7: =CH7/920000 -> 120 | CJ7: =CH7*20% -> 22080000 | CK7: 20244391 | CL7: SD NEGERI 2 BLENDER | CM7: 117760000 | CN7: =CM7/920000 -> 128 | CO7: =CM7*20% -> 23552000 | CP7: 20214693 | CQ7: SD NEGERI 2 SUTAWINANGUN | CR7: 165600000 | CS7: =CR7/920000 -> 180 | CT7: =CR7*20% -> 33120000 | CU7: 20214574 | CV7: SD NEGERI 3 SERANG | CW7: 120520000 | CX7: =CW7/920000 -> 131 | CY7: =CW7*20% -> 24104000 | CZ7: 20215216 | DA7: SD NEGERI 1 ASEM | DB7: 178480000 | DC7: =DB7/920000 -> 194 | DD7: =DB7*20% -> 35696000 | DE7: 20215446 | DF7: SD NEGERI 2 KALISARI | DG7: 269560000 | DH7: =DG7/920000 -> 293 | DI7: =DG7*20% -> 53912000 | DJ7: 20215238 | DK7: SD NEGERI 1 BANJARWANGUNAN | DL7: 683560000 | DM7: =DL7/920000 -> 743 | DN7: =DL7*20% -> 136712000 | DO7: 20244512 | DP7: SD NEGERI 3 PASURUAN | DQ7: 141680000 | DR7: =DQ7/920000 -> 154 | DS7: =DQ7*20% -> 28336000 | DT7: 20215080 | DU7: SD NEGERI 1 JATIRENGGANG | DV7: 156400000 | DW7: =DV7/920000 -> 170 | DX7: =DV7*20% -> 31280000 | DY7: 20215205 | DZ7: SD NEGERI 1 CIAWI | EA7: 216200000 | EB7: =EA7/920000 -> 235 | EC7: =EA7*20% -> 43240000 | ED7: 20214730 | EE7: SD NEGERI 2 RAWAURIP | EF7: 368000000 | EG7: =EF7/920000 -> 400 | EH7: =EF7*20% -> 73600000 | EI7: 20244369 | EJ7: UPTD SD NEGERI 1 PANGURAGAN | EK7: 226320000 | EL7: =EK7/920000 -> 246 | EM7: =EK7*20% -> 45264000 | EN7: 20215502 | EO7: SD NEGERI 1 PASALEMAN | EP7: 149960000 | EQ7: =EP7/920000 -> 163 | ER7: =EP7*20% -> 29992000 | ES7: 20215126 | ET7: SD NEGERI 1 PANEMBAHAN | EU7: 525320000 | EV7: =EU7/920000 -> 571 | EW7: =EU7*20% -> 105064000 | EX7: 20215372 | EY7: SD NEGERI 2 DANAMULYA | EZ7: 97520000 | FA7: =EZ7/920000 -> 106 | FB7: =EZ7*20% -> 19504000 | FC7: 20215064 | FD7: UPTD SD NEGERI 1 KARANG WUNI | FE7: 368920000 | FF7: =FE7/920000 -> 401 | FG7: =FE7*20% -> 73784000 | FH7: 20214617 | FI7: SD NEGERI 2 PERBUTULAN | FJ7: 180320000 | FK7: =FJ7/920000 -> 196 | FL7: =FJ7*20% -> 36064000 | FM7: 20215482 | FN7: SD NEGERI 1 SURANENGGALA KULON | FO7: 253920000 | FP7: =FO7/920000 -> 276 | FQ7: =FO7*20% -> 50784000 | FR7: 20215181 | FS7: SD NEGERI 1 BUNDER | FT7: 324760000 | FU7: =FT7/920000 -> 353 | FV7: =FT7*20% -> 64952000 | FW7: 20215296 | FX7: SD NEGERI 1 CURUGWETAN | FY7: 296240000 | FZ7: =FY7/920000 -> 322 | GA7: =FY7*20% -> 59248000 | GB7: 20215207 | GC7: SD NEGERI 1 CEMPAKA | GD7: 268640000 | GE7: =GD7/920000 -> 292 | GF7: =GD7*20% -> 53728000 | GG7: 20215250 | GH7: SD NEGERI 1 GESIK | GI7: 600760000 | GJ7: =GI7/920000 -> 653 | GK7: =GI7*20% -> 120152000 | GL7: 20215110 | GM7: SD NEGERI 1 MEKARSARI | GN7: 155480000 | GO7: =GN7/920000 -> 169 | GP7: =GN7*20% -> 31096000 | GQ7: 20214677 | GR7: SD NEGERI 2 MEGU CILIK | GS7: 127880000 | GT7: =GS7/920000 -> 139 | GU7: =GS7*20% -> 25576000
C8: 4 | D8: 20214489 | E8: SD NEGERI 3 JUNGJANG | F8: 158240000 | G8: =F8/920000 -> 172 | H8: =F8*20% -> 31648000 | I8: 20215108 | J8: SD NEGERI 1 MERTAPADA WETAN | K8: 82800000 | L8: =K8/920000 -> 90 | M8: =K8*20% -> 16560000 | N8: 20215254 | O8: SD NEGERI 1 GEMBONGANMEKAR | P8: 386400000 | Q8: =P8/920000 -> 420 | R8: =P8*20% -> 77280000 | S8: 20215285 | T8: SD NEGERI 1 CIPINANG | U8: 335800000 | V8: =U8/920000 -> 365 | W8: =U8*20% -> 67160000 | X8: 20215580 | Y8: SD NEGERI 1 TENJOMAYA | Z8: 356040000 | AA8: =Z8/920000 -> 387 | AB8: =Z8*20% -> 71208000 | AC8: 20215247 | AD8: SD NEGERI 1 GINTUNG KIDUL | AE8: 162840000 | AF8: =AE8/920000 -> 177 | AG8: =AE8*20% -> 32568000 | AH8: 20215407 | AI8: SD NEGERI 2 KEJUDEN | AJ8: 184920000 | AK8: =AJ8/920000 -> 201 | AL8: =AJ8*20% -> 36984000 | AM8: 20215289 | AN8: SD NEGERI 1 CIPANAS | AO8: 150880000 | AP8: =AO8/920000 -> 164 | AQ8: =AO8*20% -> 30176000 | AR8: 20215279 | AS8: SD NEGERI 1 GEBANGILIR | AT8: 214360000 | AU8: =AT8/920000 -> 233 | AV8: =AT8*20% -> 42872000 | AW8: 20244370 | AX8: SD NEGERI 1 PANUNGGUL | AY8: 345920000 | AZ8: =AY8/920000 -> 376 | BA8: =AY8*20% -> 69184000 | BB8: 20215130 | BC8: SD NEGERI 1 PALIMANAN BARAT | BD8: 297160000 | BE8: =BD8/920000 -> 323 | BF8: =BD8*20% -> 59432000 | BG8: 20215465 | BH8: SD NEGERI 1 SINDANGKEMPENG | BI8: 497720000 | BJ8: =BI8/920000 -> 541 | BK8: =BI8*20% -> 99544000 | BL8: 20215215 | BM8: SD NEGERI 1 ASTANA | BN8: 379960000 | BO8: =BN8/920000 -> 413 | BP8: =BN8*20% -> 75992000 | BQ8: 20244357 | BR8: SD NEGERI 1 JAMBLANG | BS8: 188600000 | BT8: =BS8/920000 -> 205 | BU8: =BS8*20% -> 37720000 | BV8: 20215573 | BW8: SD NEGERI 1 UJUNGSEMI | BX8: 278760000 | BY8: =BX8/920000 -> 303 | BZ8: =BX8*20% -> 55752000 | CA8: 20214609 | CB8: SD NEGERI 3 KERTASURA | CC8: 276000000 | CD8: =CC8/920000 -> 300 | CE8: =CC8*20% -> 55200000 | CF8: 20214592 | CG8: SD NEGERI 3 KARANGSEMBUNG | CH8: 324760000 | CI8: =CH8/920000 -> 353 | CJ8: =CH8*20% -> 64952000 | CK8: 20214749 | CL8: SD NEGERI 2 SEUSEUPAN | CM8: 84640000 | CN8: =CM8/920000 -> 92 | CO8: =CM8*20% -> 16928000 | CP8: 20214919 | CQ8: SD NEGERI 1 KEDAWUNG | CR8: 115000000 | CS8: =CR8/920000 -> 125 | CT8: =CR8*20% -> 23000000 | CU8: 20215498 | CV8: SD NEGERI 1 PEKANTINGAN | CW8: 156400000 | CX8: =CW8/920000 -> 170 | CY8: =CW8*20% -> 31280000 | CZ8: 20215584 | DA8: SD NEGERI 1 WANGKELANG | DB8: 273240000 | DC8: =DB8/920000 -> 297 | DD8: =DB8*20% -> 54648000 | DE8: 20215218 | DF8: SD NEGERI 1 AMBULU | DG8: 222640000 | DH8: =DG8/920000 -> 242 | DI8: =DG8*20% -> 44528000 | DJ8: 20214750 | DK8: SD NEGERI 2 SETUPATOK | DL8: 80960000 | DM8: =DL8/920000 -> 88 | DN8: =DL8*20% -> 16192000 | DO8: 20215138 | DP8: SD NEGERI 1 PABEDILANKALER | DQ8: 326600000 | DR8: =DQ8/920000 -> 355 | DS8: =DQ8*20% -> 65320000 | DT8: 20215426 | DU8: SD NEGERI 2 JATIRENGGANG | DV8: 187680000 | DW8: =DV8/920000 -> 204 | DX8: =DV8*20% -> 37536000 | DY8: 20215231 | DZ8: SD NEGERI 1 BEBERAN | EA8: 258520000 | EB8: =EA8/920000 -> 281 | EC8: =EA8*20% -> 51704000 | ED8: 20215013 | EE8: SD NEGERI 1 PANGARENGAN | EF8: 173880000 | EG8: =EF8/920000 -> 189 | EH8: =EF8*20% -> 34776000 | EI8: 20214634 | EJ8: SD NEGERI 2 PANGURAGAN LOR | EK8: 92920000 | EL8: =EK8/920000 -> 101 | EM8: =EK8*20% -> 18584000 | EN8: 20214645 | EO8: SD NEGERI 2 PASALEMAN | EP8: 195040000 | EQ8: =EP8/920000 -> 212 | ER8: =EP8*20% -> 39008000 | ES8: 20215581 | ET8: SD NEGERI 1 TEGALSARI | EU8: 397440000 | EV8: =EU8/920000 -> 432 | EW8: =EU8*20% -> 79488000 | EX8: 20214735 | EY8: SD NEGERI 2 PLUMBON | EZ8: 175720000 | FA8: =EZ8/920000 -> 191 | FB8: =EZ8*20% -> 35144000 | FC8: 20214731 | FD8: SD NEGERI 2 PUTAT | FE8: 241960000 | FF8: =FE8/920000 -> 263 | FG8: =FE8*20% -> 48392000 | FH8: 20214638 | FI8: SD NEGERI 2 PEJAMBON | FJ8: 116840000 | FK8: =FJ8/920000 -> 127 | FL8: =FJ8*20% -> 23368000 | FM8: 20215485 | FN8: SD NEGERI 1 SURAKARTA | FO8: 314640000 | FP8: =FO8/920000 -> 342 | FQ8: =FO8*20% -> 62928000 | FR8: 20214944 | FS8: SD NEGERI 3 SUSUKAN | FT8: 106720000 | FU8: =FT8/920000 -> 116 | FV8: =FT8*20% -> 21344000 | FW8: 20215202 | FX8: SD NEGERI 1 CIAWIJAPURA | FY8: 178480000 | FZ8: =FY8/920000 -> 194 | GA8: =FY8*20% -> 35696000 | GB8: 20215059 | GC8: SD NEGERI 1 KECOMBERAN | GD8: 289800000 | GE8: =GD8/920000 -> 315 | GF8: =GD8*20% -> 57960000 | GG8: 20215314 | GH8: SD NEGERI 2 GESIK | GI8: 223560000 | GJ8: =GI8/920000 -> 243 | GK8: =GI8*20% -> 44712000 | GL8: 20215570 | GM8: SD NEGERI 1 WALEDDESA | GN8: 275080000 | GO8: =GN8/920000 -> 299 | GP8: =GN8*20% -> 55016000 | GQ8: 20215592 | GR8: UPTD SD NEGERI 1 WERU KIDUL | GS8: 539120000 | GT8: =GS8/920000 -> 586 | GU8: =GS8*20% -> 107824000
C9: 5 | D9: 20215505 | E9: SD NEGERI 1 RAWAGATEL | F9: 87400000 | G9: =F9/920000 -> 95 | H9: =F9*20% -> 17480000 | I9: 20215214 | J9: SD NEGERI 1 ASTANAJAPURA | K9: 203320000 | L9: =K9/920000 -> 221 | M9: =K9*20% -> 40664000 | N9: 20215253 | O9: SD NEGERI 1 GEMBONGAN | P9: 293480000 | Q9: =P9/920000 -> 319 | R9: =P9*20% -> 58696000 | S9: 20244396 | T9: SD NEGERI 2 CIAWIGAJAH | U9: 312800000 | V9: =U9/920000 -> 340 | W9: =U9*20% -> 62560000 | X9: 20215549 | Y9: SD NEGERI 2 BOJONGNEGARA | Z9: 143520000 | AA9: =Z9/920000 -> 156 | AB9: =Z9*20% -> 28704000 | AC9: 20215299 | AD9: SD NEGERI 1 GALAGAMBA | AE9: 226320000 | AF9: =AE9/920000 -> 246 | AG9: =AE9*20% -> 45264000 | AH9: 20215599 | AI9: SD NEGERI 1 WARUKAWUNG | AJ9: 478400000 | AK9: =AJ9/920000 -> 520 | AL9: =AJ9*20% -> 95680000 | AM9: 20215541 | AN9: SD NEGERI 2 CANGKOAK | AO9: 161000000 | AP9: =AO9/920000 -> 175 | AQ9: =AO9*20% -> 32200000 | AR9: 20215324 | AS9: SD NEGERI 2 GEBANGILIR | AT9: 120520000 | AU9: =AT9/920000 -> 131 | AV9: =AT9*20% -> 24104000 | AW9: 20215413 | AX9: SD NEGERI 2 KEDUNGDALEM | AY9: 161000000 | AZ9: =AY9/920000 -> 175 | BA9: =AY9*20% -> 32200000 | BB9: 20215173 | BC9: SD NEGERI 1 KEDUNGBUNDER | BD9: 185840000 | BE9: =BD9/920000 -> 202 | BF9: =BD9*20% -> 37168000 | BG9: 20215338 | BH9: SD NEGERI 2 GUMULUNG TONGGOH | BI9: 253920000 | BJ9: =BI9/920000 -> 276 | BK9: =BI9*20% -> 50784000 | BL9: 20214558 | BM9: SD NEGERI 3 SIRNABAYA | BN9: 90160000 | BO9: =BN9/920000 -> 98 | BP9: =BN9*20% -> 18032000 | BQ9: 20215122 | BR9: SD NEGERI 1 ORIMALANG | BS9: 138920000 | BT9: =BS9/920000 -> 151 | BU9: =BS9*20% -> 27784000 | BV9: 20215102 | BW9: SD NEGERI 1 KALIDERES | BX9: 207000000 | BY9: =BX9/920000 -> 225 | BZ9: =BX9*20% -> 41400000 | CA9: 20214667 | CB9: SD NEGERI 2 KERTASURA | CC9: 216200000 | CD9: =CC9/920000 -> 235 | CE9: =CC9*20% -> 43240000 | CF9: 20215045 | CG9: SD NEGERI 1 KARANGMEKAR | CH9: 189520000 | CI9: =CH9/920000 -> 206 | CJ9: =CH9*20% -> 37904000 | CK9: 20215508 | CL9: SD NEGERI 1 SEUSEUPAN | CM9: 79120000 | CN9: =CM9/920000 -> 86 | CO9: =CM9*20% -> 15824000 | CP9: 20215476 | CQ9: SD NEGERI 1 SUTAWINANGUN | CR9: 109480000 | CS9: =CR9/920000 -> 119 | CT9: =CR9*20% -> 21896000 | CU9: 20214637 | CV9: SD NEGERI 2 PEKANTINGAN | CW9: 227240000 | CX9: =CW9/920000 -> 247 | CY9: =CW9*20% -> 45448000 | CZ9: 20215464 | DA9: UPTD SD NEGERI 1 SINDANGLAUT | DB9: 349600000 | DC9: =DB9/920000 -> 380 | DD9: =DB9*20% -> 69920000 | DE9: 20214668 | DF9: SD NEGERI 2 LOSARI LOR | DG9: 151800000 | DH9: =DG9/920000 -> 165 | DI9: =DG9*20% -> 30360000 | DJ9: 20215497 | DK9: SD NEGERI 1 PENPEN | DL9: 268640000 | DM9: =DL9/920000 -> 292 | DN9: =DL9*20% -> 53728000 | DO9: 20244372 | DP9: SD NEGERI 1 PASURUAN | DQ9: 278760000 | DR9: =DQ9/920000 -> 303 | DS9: =DQ9*20% -> 55752000 | DT9: 20215266 | DU9: SD NEGERI 1 HULUBANTENG | DV9: 145360000 | DW9: =DV9/920000 -> 158 | DX9: =DV9*20% -> 29072000 | DY9: 20214624 | DZ9: SD NEGERI 2 PALIMANAN TIMUR | EA9: 241960000 | EB9: =EA9/920000 -> 263 | EC9: =EA9*20% -> 48392000 | ED9: 20214899 | EE9: SD NEGERI 1 ASTANAMUKTI | EF9: 150880000 | EG9: =EF9/920000 -> 164 | EH9: =EF9*20% -> 30176000 | EI9: 20215104 | EJ9: SD NEGERI 1 PANGURAGAN LOR | EK9: 216200000 | EL9: =EK9/920000 -> 235 | EM9: =EK9*20% -> 43240000 | EN9: 20215473 | EO9: SD NEGERI 1 TANJUNG ANOM | EP9: 172960000 | EQ9: =EP9/920000 -> 188 | ER9: =EP9*20% -> 34592000 | ES9: 20244377 | ET9: SD NEGERI 1 SARABAU | EU9: 132480000 | EV9: =EU9/920000 -> 144 | EW9: =EU9*20% -> 26496000 | EX9: 20214733 | EY9: SD NEGERI 2 PURBAWINANGUN | EZ9: 266800000 | FA9: =EZ9/920000 -> 290 | FB9: =EZ9*20% -> 53360000 | FC9: 20215512 | FD9: UPTD SD NEGERI 1 SEDONG LOR | FE9: 221720000 | FF9: =FE9/920000 -> 241 | FG9: =FE9*20% -> 44344000 | FH9: 20214713 | FI9: SD NEGERI 2 TUKMUDAL | FJ9: 375360000 | FK9: =FJ9/920000 -> 408 | FL9: =FJ9*20% -> 75072000 | FM9: 20214963 | FN9: SD NEGERI 3 SURAKARTA | FO9: 79120000 | FP9: =FO9/920000 -> 86 | FQ9: =FO9*20% -> 15824000 | FR9: 20215246 | FS9: SD NEGERI 1 GINTUNGLOR | FT9: 289800000 | FU9: =FT9/920000 -> 315 | FV9: =FT9*20% -> 57960000 | FW9: 20214522 | FX9: SD NEGERI 3 CIAWIASIH | FY9: 158240000 | FZ9: =FY9/920000 -> 172 | GA9: =FY9*20% -> 31648000 | GB9: 20215400 | GC9: SD NEGERI 2 KECOMBERAN | GD9: 103040000 | GE9: =GD9/920000 -> 112 | GF9: =GD9*20% -> 20608000 | GG9: 20214898 | GH9: SD NEGERI 1 ASTAPADA | GI9: 360640000 | GJ9: =GI9/920000 -> 392 | GK9: =GI9*20% -> 72128000 | GL9: 20215052 | GM9: SD NEGERI 1 KARANGSARI | GN9: 337640000 | GO9: =GN9/920000 -> 367 | GP9: =GN9*20% -> 67528000 | GQ9: 20244360 | GR9: UPTD SD NEGERI 1 KARANGSARI | GS9: 456320000 | GT9: =GS9/920000 -> 496 | GU9: =GS9*20% -> 91264000
C10: 6 | D10: 20215037 | E10: SD NEGERI 1 KARANGSAMBUNG | F10: 230000000 | G10: =F10/920000 -> 250 | H10: =F10*20% -> 46000000 | I10: 20214675 | J10: SD NEGERI 2 MERTAPADA KULON | K10: 189520000 | L10: =K10/920000 -> 206 | M10: =K10*20% -> 37904000 | N10: 20214523 | O10: SD NEGERI 3 CANGKUANG | P10: 200560000 | Q10: =P10/920000 -> 218 | R10: =P10*20% -> 40112000 | S10: 20215360 | T10: SD NEGERI 2 CIKANCAS | U10: 182160000 | V10: =U10/920000 -> 198 | W10: =U10*20% -> 36432000 | X10: 20244363 | Y10: UPTD SD NEGERI 1 LEUWEUNGGAJAH | Z10: 327520000 | AA10: =Z10/920000 -> 356 | AB10: =Z10*20% -> 65504000 | AC10: 20215183 | AD10: SD NEGERI 1 BUDUR | AE10: 292560000 | AF10: =AE10/920000 -> 318 | AG10: =AE10*20% -> 58512000 | AH10: 20214586 | AI10: SD NEGERI 3 KASUGENGAN KIDUL | AJ10: 119600000 | AK10: =AJ10/920000 -> 130 | AL10: =AJ10*20% -> 23920000 | AM10: 20215563 | AN10: SD NEGERI 2 BOBOS | AO10: 116840000 | AP10: =AO10/920000 -> 127 | AQ10: =AO10*20% -> 23368000 | AR10: 20215321 | AS10: SD NEGERI 2 GEBANG UDIK | AT10: 159160000 | AU10: =AT10/920000 -> 173 | AV10: =AT10*20% -> 31832000 | AW10: 20214501 | AX10: SD NEGERI 3 GEGESIK KULON | AY10: 73600000 | AZ10: =AY10/920000 -> 80 | BA10: =AY10*20% -> 14720000 | BB10: 20215412 | BC10: SD NEGERI 2 KEDUNGBUNDER | BD10: 199640000 | BE10: =BD10/920000 -> 217 | BF10: =BD10*20% -> 39928000 | BG10: 20215348 | BH10: SD NEGERI 2 DURAJAYA | BI10: 319240000 | BJ10: =BI10/920000 -> 347 | BK10: =BI10*20% -> 63848000 | BL10: 20215542 | BM10: SD NEGERI 2 BUYUT | BN10: 80960000 | BO10: =BN10/920000 -> 88 | BP10: =BN10*20% -> 16192000 | BQ10: 20215242 | BR10: SD NEGERI 1 BAKUNGLOR | BS10: 121440000 | BT10: =BS10/920000 -> 132 | BU10: =BS10*20% -> 24288000 | BV10: 20244509 | BW10: SD NEGERI 2 UJUNGSEMI | BX10: 248400000 | BY10: =BX10/920000 -> 270 | BZ10: =BX10*20% -> 49680000 | CA10: 20215544 | CB10: SD NEGERI 2 BUNGKO LOR | CC10: 173880000 | CD10: =CC10/920000 -> 189 | CE10: =CC10*20% -> 34776000 | CF10: 20215043 | CG10: SD NEGERI 1 KARANGSUWUNG | CH10: 204240000 | CI10: =CH10/920000 -> 222 | CJ10: =CH10*20% -> 40848000 | CK10: 20215041 | CL10: UPTD SD NEGERI 1 KARANGASEM | CM10: 420440000 | CN10: =CM10/920000 -> 457 | CO10: =CM10*20% -> 84088000 | CP10: 20214736 | CQ10: SD NEGERI 2 PILANGSARI | CR10: 175720000 | CS10: =CR10/920000 -> 191 | CT10: =CR10*20% -> 35144000 | CU10: 20215170 | CV10: SD NEGERI 1 KREYO | CW10: 154560000 | CX10: =CW10/920000 -> 168 | CY10: =CW10*20% -> 30912000 | CZ10: 20215162 | DA10: SD NEGERI 1 LEMAHABANG | DB10: 130640000 | DC10: =DB10/920000 -> 142 | DD10: =DB10*20% -> 26128000 | DE10: 20215125 | DF10: SD NEGERI 1 PANGGANGSARI | DG10: 111320000 | DH10: =DG10/920000 -> 121 | DI10: =DG10*20% -> 22264000 | DJ10: 20214635 | DK10: SD NEGERI 2 PENPEN | DL10: 351440000 | DM10: =DL10/920000 -> 382 | DN10: =DL10*20% -> 70288000 | DO10: 20215136 | DP10: UPTD SD NEGERI 1 PABEDILAN KULON | DQ10: 491280000 | DR10: =DQ10/920000 -> 534 | DS10: =DQ10*20% -> 98256000 | DT10: 20215334 | DU10: SD NEGERI 2 HULUBANTENG | DV10: 144440000 | DW10: =DV10/920000 -> 157 | DX10: =DV10*20% -> 28888000 | DY10: 20215364 | DZ10: SD NEGERI 2 CIAWI | EA10: 93840000 | EB10: =EA10/920000 -> 102 | EC10: =EA10*20% -> 18768000 | ED10: 20215249 | EE10: SD NEGERI 1 GETRAKMOYAN | EF10: 442520000 | EG10: =EF10/920000 -> 481 | EH10: =EF10*20% -> 88504000 | EI10: 20214654 | EJ10: SD NEGERI 2 LEMAHTAMBA | EK10: 194120000 | EL10: =EK10/920000 -> 211 | EM10: =EK10*20% -> 38824000 | EN10: 20214690 | EO10: SD NEGERI 2 TANJUNGANOM | EP10: 156400000 | EQ10: =EP10/920000 -> 170 | ER10: =EP10*20% -> 31280000 | ES10: 20215191 | ET10: SD NEGERI 1 CANGKRING | EU10: 258520000 | EV10: =EU10/920000 -> 281 | EW10: =EU10*20% -> 51704000 | EX10: 20244375 | EY10: SD NEGERI 1 PURBAWINANGUN | EZ10: 284280000 | FA10: =EZ10/920000 -> 309 | FB10: =EZ10*20% -> 56856000 | FC10: 20214511 | FD10: SD NEGERI 2 WINDUJAYA | FE10: 157320000 | FF10: =FE10/920000 -> 171 | FG10: =FE10*20% -> 31464000 | FH10: 20214571 | FI10: SD NEGERI 3 SIDAWANGI | FJ10: 155480000 | FK10: =FJ10/920000 -> 169 | FL10: =FJ10*20% -> 31096000 | FM10: 20215143 | FN10: SD NEGERI 1 KERATON | FO10: 284280000 | FP10: =FO10/920000 -> 309 | FQ10: =FO10*20% -> 56856000 | FR10: 20215408 | FS10: SD NEGERI 2 KEJIWAN | FT10: 361560000 | FU10: =FT10/920000 -> 393 | FV10: =FT10*20% -> 72312000 | FW10: 20215418 | FX10: SD NEGERI 2 KALIGAWE | FY10: 126040000 | FZ10: =FY10/920000 -> 137 | GA10: =FY10*20% -> 25208000 | GB10: 20215401 | GC10: SD NEGERI 2 KEPONGPONGAN | GD10: 318320000 | GE10: =GD10/920000 -> 346 | GF10: =GD10*20% -> 63664000 | GG10: 20215525 | GH10: SD NEGERI 2 BATEMBAT | GI10: 175720000 | GJ10: =GI10/920000 -> 191 | GK10: =GI10*20% -> 35144000 | GL10: 20215281 | GM10: SD NEGERI 1 CIUYAH | GN10: 165600000 | GO10: =GN10/920000 -> 180 | GP10: =GN10*20% -> 33120000 | GQ10: 20214907 | GR10: SD NEGERI 2 TEGALWANGI | GS10: 379040000 | GT10: =GS10/920000 -> 412 | GU10: =GS10*20% -> 75808000
C11: 7 | D11: 20215511 | E11: SD NEGERI 1 SENDE | F11: 283360000 | G11: =F11/920000 -> 308 | H11: =F11*20% -> 56672000 | I11: 20215438 | J11: SD NEGERI 2 KANCIKULON | K11: 270480000 | L11: =K11/920000 -> 294 | M11: =K11*20% -> 54096000 | N11: 20215189 | O11: SD NEGERI 1 BOJONGGEBANG | P11: 178480000 | Q11: =P11/920000 -> 194 | R11: =P11*20% -> 35696000 | S11: 20215538 | T11: SD NEGERI 2 BEBER | U11: 166520000 | V11: =U11/920000 -> 181 | W11: =U11*20% -> 33304000 | X11: 20214483 | Y11: SD NEGERI 3 CILEDUG LOR | Z11: 106720000 | AA11: =Z11/920000 -> 116 | AB11: =Z11*20% -> 21344000 | AC11: 20215327 | AD11: SD NEGERI 2 GALAGAMBA | AE11: 196880000 | AF11: =AE11/920000 -> 214 | AG11: =AE11*20% -> 39376000 | AH11: 20214585 | AI11: SD NEGERI 3 KASUGENGAN LOR | AJ11: 154560000 | AK11: =AJ11/920000 -> 168 | AL11: =AJ11*20% -> 30912000 | AM11: 20214744 | AN11: SD NEGERI 2 SINDANGJAWA | AO11: 131560000 | AP11: =AO11/920000 -> 143 | AQ11: =AO11*20% -> 26312000 | AR11: 20215306 | AS11: UPTD SD NEGERI 1 DOMPYONG WETAN | AT11: 322920000 | AU11: =AT11/920000 -> 351 | AV11: =AT11*20% -> 64584000 | AW11: 20215313 | AX11: SD NEGERI 2 JAGAPURA LOR | AY11: 266800000 | AZ11: =AY11/920000 -> 290 | BA11: =AY11*20% -> 53360000 | BB11: 20214583 | BC11: SD NEGERI 3 KEDUNGBUNDER | BD11: 211600000 | BE11: =BD11/920000 -> 230 | BF11: =BD11*20% -> 42320000 | BG11: 20215339 | BH11: SD NEGERI 2 GUMULUNGLEBAK | BI11: 323840000 | BJ11: =BI11/920000 -> 352 | BK11: =BI11*20% -> 64768000 | BL11: 20214605 | BM11: SD NEGERI 3 KLAYAN | BN11: 156400000 | BO11: =BN11/920000 -> 170 | BP11: =BN11*20% -> 31280000 | BQ11: 20215594 | BR11: SD NEGERI 1 WANGUNHARJA | BS11: 138000000 | BT11: =BS11/920000 -> 150 | BU11: =BS11*20% -> 27600000 | BV11: 20215490 | BW11: SD NEGERI 1 PRAJAWINANGUN KULON | BX11: 210680000 | BY11: =BX11/920000 -> 229 | BZ11: =BX11*20% -> 42136000 | CA11: 20215305 | CB11: SD NEGERI 1 DUKUH | CC11: 305440000 | CD11: =CC11/920000 -> 332 | CE11: =CC11*20% -> 61088000 | CF11: 20215389 | CG11: SD NEGERI 2 KARANGTENGAH | CH11: 303600000 | CI11: =CH11/920000 -> 330 | CJ11: =CH11*20% -> 60720000 | CK11: 20215042 | CL11: SD NEGERI 1 KARANGANYAR | CM11: 106720000 | CN11: =CM11/920000 -> 116 | CO11: =CM11*20% -> 21344000 | CP11: 20215411 | CQ11: SD NEGERI 2 KEDUNGDAWA | CR11: 200560000 | CS11: =CR11/920000 -> 218 | CT11: =CR11*20% -> 40112000 | CU11: 20214664 | CV11: SD NEGERI 2 KLANGENAN | CW11: 517960000 | CX11: =CW11/920000 -> 563 | CY11: =CW11*20% -> 103592000 | CZ11: 20214726 | DA11: SD NEGERI 2 SARAJAYA | DB11: 151800000 | DC11: =DB11/920000 -> 165 | DD11: =DB11*20% -> 30360000 | DE11: 20214914 | DF11: SD NEGERI MULYASARI | DG11: 21160000 | DH11: =DG11/920000 -> 23 | DI11: =DG11*20% -> 4232000 | DJ11: 20214684 | DK11: SD NEGERI 2 LUWUNG | DL11: 291640000 | DM11: =DL11/920000 -> 317 | DN11: =DL11*20% -> 58328000 | DO11: 20215367 | DP11: SD NEGERI 1 DUKUHWIDARA | DQ11: 134320000 | DR11: =DQ11/920000 -> 146 | DS11: =DQ11*20% -> 26864000 | DT11: 20244354 | DU11: UPTD SD NEGERI 1 HULUBANTENG LOR | DV11: 298080000 | DW11: =DV11/920000 -> 324 | DX11: =DV11*20% -> 59616000 | DY11: 20214538 | DZ11: SD NEGERI 3 PEGAGAN | EA11: 126960000 | EB11: =EA11/920000 -> 138 | EC11: =EA11*20% -> 25392000 | ED11: 20244390 | EE11: SD NEGERI 2 BERINGIN | EF11: 147200000 | EG11: =EF11/920000 -> 160 | EH11: =EF11*20% -> 29440000 | EI11: 20215086 | EJ11: SD NEGERI 1 KALIANYAR | EK11: 224480000 | EL11: =EK11/920000 -> 244 | EM11: =EK11*20% -> 44896000 | EN11: 20214938 | EO11: SD NEGERI 3 TONJONG | EP11: 92000000 | EQ11: =EP11/920000 -> 100 | ER11: =EP11*20% -> 18400000 | ES11: 20214704 | ET11: SD NEGERI 2 TEGALSARI | EU11: 113160000 | EV11: =EU11/920000 -> 123 | EW11: =EU11*20% -> 22632000 | EX11: 20244349 | EY11: SD NEGERI 1 Cempaka | EZ11: 344080000 | FA11: =EZ11/920000 -> 374 | FB11: =EZ11*20% -> 68816000 | FC11: 20215515 | FD11: UPTD SD NEGERI 1 SEDONG KIDUL | FE11: 281520000 | FF11: =FE11/920000 -> 306 | FG11: =FE11*20% -> 56304000 | FH11: 20215088 | FI11: SD NEGERI 1 KALIWADAS | FJ11: 352360000 | FK11: =FJ11/920000 -> 383 | FL11: =FJ11*20% -> 70472000 | FM11: 20215489 | FN11: SD NEGERI 1 PURWAWINANGUN | FO11: 470120000 | FP11: =FO11/920000 -> 511 | FQ11: =FO11*20% -> 94024000 | FR11: 20215103 | FS11: SD NEGERI 1 JATIANOM | FT11: 218960000 | FU11: =FT11/920000 -> 238 | FV11: =FT11*20% -> 43792000 | FW11: 20215588 | FX11: SD NEGERI 1 WILULANG | FY11: 102120000 | FZ11: =FY11/920000 -> 111 | GA11: =FY11*20% -> 20424000 | GB11: 20214613 | GC11: SD NEGERI 3 KEPONGPONGAN | GD11: 96600000 | GE11: =GD11/920000 -> 105 | GF11: =GD11*20% -> 19320000 | GG11: 20215034 | GH11: SD NEGERI 1 PALIR | GI11: 195040000 | GJ11: =GI11/920000 -> 212 | GK11: =GI11*20% -> 39008000 | GL11: 20215376 | GM11: SD NEGERI 2 CIUYAH | GN11: 204240000 | GO11: =GN11/920000 -> 222 | GP11: =GN11*20% -> 40848000 | GQ11: 20244379 | GR11: SD NEGERI 1 SETU WETAN | GS11: 150880000 | GT11: =GS11/920000 -> 164 | GU11: =GS11*20% -> 30176000
C12: 8 | D12: 20214506 | E12: SD NEGERI 3 ARJAWINANGUN | F12: 626520000 | G12: =F12/920000 -> 681 | H12: =F12*20% -> 125304000 | I12: 20214493 | J12: SD NEGERI 3 JAPURA KIDUL | K12: 43240000 | L12: =K12/920000 -> 47 | M12: =K12*20% -> 8648000 | N12: 20215561 | O12: SD NEGERI 2 BOJONGGEBANG | P12: 92920000 | Q12: =P12/920000 -> 101 | R12: =P12*20% -> 18584000 | S12: 20215203 | T12: SD NEGERI 1 CIAWIGAJAH | U12: 271400000 | V12: =U12/920000 -> 295 | W12: =U12*20% -> 54280000 | X12: 20215079 | Y12: SD NEGERI 1 JATISEENG | Z12: 406640000 | AA12: =Z12/920000 -> 442 | AB12: =Z12*20% -> 81328000 | AC12: 20215375 | AD12: SD NEGERI 2 CIWARINGIN | AE12: 155480000 | AF12: =AE12/920000 -> 169 | AG12: =AE12*20% -> 31096000 | AH12: 20215057 | AI12: SD NEGERI 1 KEDUANAN | AJ12: 231840000 | AK12: =AJ12/920000 -> 252 | AL12: =AJ12*20% -> 46368000 | AM12: 20215198 | AN12: SD NEGERI 1 CIKALAHANG | AO12: 174800000 | AP12: =AO12/920000 -> 190 | AQ12: =AO12*20% -> 34960000 | AR12: 20215300 | AS12: SD NEGERI 1 GAGASARI | AT12: 364320000 | AU12: =AT12/920000 -> 396 | AV12: =AT12*20% -> 72864000 | AW12: 20215458 | AX12: SD NEGERI 1 SIBUBUT | AY12: 178480000 | AZ12: =AY12/920000 -> 194 | BA12: =AY12*20% -> 35696000 | BB12: 20215358 | BC12: SD NEGERI 2 CIKEUSAL | BD12: 157320000 | BE12: =BD12/920000 -> 171 | BF12: =BD12*20% -> 31464000 | BG12: 20215275 | BH12: SD NEGERI 1 GREGED | BI12: 297160000 | BJ12: =BI12/920000 -> 323 | BK12: =BI12*20% -> 59432000 | BL12: 20214525 | BM12: SD NEGERI 3 BUYUT | BN12: 230920000 | BO12: =BN12/920000 -> 251 | BP12: =BN12*20% -> 46184000 | BQ12: 20214721 | BR12: SD NEGERI 2 SITIWINANGUN | BS12: 113160000 | BT12: =BS12/920000 -> 123 | BU12: =BS12*20% -> 22632000 | BV12: 20244374 | BW12: SD NEGERI 1 PRAJAWINANGUN WETAN | BX12: 330280000 | BY12: =BX12/920000 -> 359 | BZ12: =BX12*20% -> 66056000 | CA12: 20244342 | CB12: SD NEGERI 1 GROGOL | CC12: 418600000 | CD12: =CC12/920000 -> 455 | CE12: =CC12*20% -> 83720000 | CF12: 20214593 | CG12: SD NEGERI 3 KARANGMEKAR | CH12: 148120000 | CI12: =CH12/920000 -> 161 | CJ12: =CH12*20% -> 29624000 | CK12: 20215168 | CL12: SD NEGERI 1 KUBANGDELEG | CM12: 212520000 | CN12: =CM12/920000 -> 231 | CO12: =CM12*20% -> 42504000 | CP12: 20214607 | CQ12: SD NEGERI 3 KERTAWINANGUN | CR12: 179400000 | CS12: =CR12/920000 -> 195 | CT12: =CR12*20% -> 35880000 | CU12: 20215309 | CV12: SD NEGERI 1 DANAWINANGUN | CW12: 173880000 | CX12: =CW12/920000 -> 189 | CY12: =CW12*20% -> 34776000 | CZ12: 20215381 | DA12: SD NEGERI 2 CIPEUJEUH KULON | DB12: 270480000 | DC12: =DB12/920000 -> 294 | DD12: =DB12*20% -> 54096000 | DE12: 20215213 | DF12: SD NEGERI 1 ASTANALANGGAR | DG12: 396520000 | DH12: =DG12/920000 -> 431 | DI12: =DG12*20% -> 79304000 | DJ12: 20215002 | DK12: SD NEGERI 1 WARUDUWUR | DL12: 201480000 | DM12: =DL12/920000 -> 219 | DN12: =DL12*20% -> 40296000 | DO12: 20214472 | DP12: SD NEGERI 2 DUKUHWIDARA | DQ12: 112240000 | DR12: =DQ12/920000 -> 122 | DS12: =DQ12*20% -> 22448000 | DT12: 20215455 | DU12: SD NEGERI 1 SUKADANA | DV12: 270480000 | DW12: =DV12/920000 -> 294 | DX12: =DV12*20% -> 54096000 | DY12: 20214611 | DZ12: SD NEGERI 3 KEPUH | EA12: 69000000 | EB12: =EA12/920000 -> 75 | EC12: =EA12*20% -> 13800000 | ED12: 20215015 | EE12: SD NEGERI 1 PANGENAN | EF12: 181240000 | EG12: =EF12/920000 -> 197 | EH12: =EF12*20% -> 36248000 | EI12: 20215420 | EJ12: SD NEGERI 2 KALIANYAR | EK12: 94760000 | EL12: =EK12/920000 -> 103 | EM12: =EK12*20% -> 18952000 | EN12: 20246448 | EO12: SD NEGERI 2 CIGOBANG | EP12: 147200000 | EQ12: =EP12/920000 -> 160 | ER12: =EP12*20% -> 29440000 | ES12: 20214619 | ET12: SD NEGERI 2 PANGKALAN | EU12: 108560000 | EV12: =EU12/920000 -> 118 | EW12: =EU12*20% -> 21712000 | EX12: 20214685 | EY12: SD NEGERI 2 LURAH | EZ12: 197800000 | FA12: =EZ12/920000 -> 215 | FB12: =EZ12*20% -> 39560000 | FC12: 20246439 | FD12: SD NEGERI 1 PANONGANLOR | FE12: 276000000 | FF12: =FE12/920000 -> 300 | FG12: =FE12*20% -> 55200000 | FH12: 20215405 | FI12: SD NEGERI 2 KEMANTREN | FJ12: 188600000 | FK12: =FJ12/920000 -> 205 | FL12: =FJ12*20% -> 37720000 | FM12: 20214697 | FN12: SD NEGERI 2 SURANENGGALA KULON | FO12: 123280000 | FP12: =FO12/920000 -> 134 | FQ12: =FO12*20% -> 24656000 | FR12: 20215117 | FS12: SD NEGERI 1 LUWUNGKENCANA | FT12: 189520000 | FU12: =FT12/920000 -> 206 | FV12: =FT12*20% -> 37904000 | FW12: 20215479 | FX12: SD NEGERI 1 SUSUKANAGUNG | FY12: 201480000 | FZ12: =FY12/920000 -> 219 | GA12: =FY12*20% -> 40296000 | GB12: 20215144 | GC12: SD NEGERI 1 KERANDON | GD12: 339480000 | GE12: =GD12/920000 -> 369 | GF12: =GD12*20% -> 67896000 | GG12: 20215308 | GH12: SD NEGERI 1 DAWUAN | GI12: 253000000 | GJ12: =GI12/920000 -> 275 | GK12: =GI12*20% -> 50600000 | GL12: 20215585 | GM12: SD NEGERI 2 AMBIT | GN12: 106720000 | GO12: =GN12/920000 -> 116 | GP12: =GN12*20% -> 21344000 | GQ12: 20215591 | GR12: UPTD SD NEGERI 1 WERU LOR | GS12: 544640000 | GT12: =GS12/920000 -> 592 | GU12: =GS12*20% -> 108928000
C13: 9 | D13: 20214688 | E13: SD NEGERI 2 TEGALGUBUG | F13: 106720000 | G13: =F13/920000 -> 116 | H13: =F13*20% -> 21344000 | I13: 20215245 | J13: SD NEGERI 1 JAPURABAKTI | K13: 209760000 | L13: =K13/920000 -> 228 | M13: =K13*20% -> 41952000 | N13: 20215009 | O13: SD NEGERI 1 SERANGWETAN | P13: 161920000 | Q13: =P13/920000 -> 176 | R13: =P13*20% -> 32384000 | S13: 20246441 | T13: SD NEGERI 1 PATAPAN | U13: 155480000 | V13: =U13/920000 -> 169 | W13: =U13*20% -> 31096000 | X13: 20215293 | Y13: SD NEGERI 1 CILEDUG WETAN | Z13: 106720000 | AA13: =Z13/920000 -> 116 | AB13: =Z13*20% -> 21344000 | AC13: 20215184 | AD13: SD NEGERI 1 BRINGIN | AE13: 195040000 | AF13: =AE13/920000 -> 212 | AG13: =AE13*20% -> 39008000 | AH13: 20214924 | AI13: SD NEGERI 1 GETASAN | AJ13: 355120000 | AK13: =AJ13/920000 -> 386 | AL13: =AJ13*20% -> 71024000 | AM13: 20214682 | AN13: SD NEGERI 2 MANDALA | AO13: 103960000 | AP13: =AO13/920000 -> 113 | AQ13: =AO13*20% -> 20792000 | AR13: 20215093 | AS13: SD NEGERI 1 KALIPASUNG | AT13: 425040000 | AU13: =AT13/920000 -> 462 | AV13: =AT13*20% -> 85008000 | AW13: 20215320 | AX13: SD NEGERI 2 GEGESIK KIDUL | AY13: 180320000 | AZ13: =AY13/920000 -> 196 | BA13: =AY13*20% -> 36064000 | BB13: 20215195 | BC13: SD NEGERI 1 CIKEUSAL | BD13: 111320000 | BE13: =BD13/920000 -> 121 | BF13: =BD13*20% -> 22264000 | BG13: 20215049 | BH13: SD NEGERI 1 KAMARANG LEBAK | BI13: 103040000 | BJ13: =BI13/920000 -> 112 | BK13: =BI13*20% -> 20608000 | BL13: 20215274 | BM13: SD NEGERI 1 GROGOL | BN13: 254840000 | BO13: =BN13/920000 -> 277 | BP13: =BN13*20% -> 50968000 | BQ13: 20215548 | BR13: SD NEGERI 2 BOJONG WETAN | BS13: 299920000 | BT13: =BS13/920000 -> 326 | BU13: =BS13*20% -> 59984000 | BV13: 20215595 | BW13: SD NEGERI 1 WARGABINANGUN | BX13: 195040000 | BY13: =BX13/920000 -> 212 | BZ13: =BX13*20% -> 39008000 | CA13: 20244344 | CB13: SD NEGERI 1 PEGAGAN KIDUL | CC13: 527160000 | CD13: =CC13/920000 -> 573 | CE13: =CC13*20% -> 105432000 | CF13: 20215450 | CG13: SD NEGERI 2 KALIMEANG | CH13: 128800000 | CI13: =CH13/920000 -> 140 | CJ13: =CH13*20% -> 25760000 | CK13: 20215082 | CL13: SD NEGERI 1 JATIPIRING | CM13: 168360000 | CN13: =CM13/920000 -> 183 | CO13: =CM13*20% -> 33672000 | CP13: 20244362 | CQ13: SD NEGERI 1 KERTAWINANGUN | CR13: 211600000 | CS13: =CR13/920000 -> 230 | CT13: =CR13*20% -> 42320000 | CU13: 20215460 | CV13: SD NEGERI 1 SLANGIT | CW13: 235520000 | CX13: =CW13/920000 -> 256 | CY13: =CW13*20% -> 47104000 | CZ13: 20214479 | DA13: SD NEGERI 3 CIPEUJEUH WETAN | DB13: 323840000 | DC13: =DB13/920000 -> 352 | DD13: =DB13*20% -> 64768000 | DE13: 20214505 | DF13: SD NEGERI 3 ASTANALANGGAR | DG13: 149040000 | DH13: =DG13/920000 -> 162 | DI13: =DG13*20% -> 29808000 | DJ13: 20214897 | DK13: SD NEGERI 1 BANDENGAN | DL13: 157320000 | DM13: =DL13/920000 -> 171 | DN13: =DL13*20% -> 31464000 | DO13: 20215137 | DP13: SD NEGERI 1 PABEDILANKIDUL | DQ13: 210680000 | DR13: =DQ13/920000 -> 229 | DS13: =DQ13*20% -> 42136000 | DT13: 20215132 | DU13: UPTD SD NEGERI 1 PABUARAN WETAN | DV13: 322000000 | DW13: =DV13/920000 -> 350 | DX13: =DV13*20% -> 64400000 | DY13: 20214669 | DZ13: SD NEGERI 2 LUNGBENDA | EA13: 207000000 | EB13: =EA13/920000 -> 225 | EC13: =EA13*20% -> 41400000 | ED13: 20215301 | EE13: SD NEGERI 1 ENDER | EF13: 131560000 | EG13: =EF13/920000 -> 143 | EH13: =EF13*20% -> 26312000 | EI13: 20214541 | EJ13: SD NEGERI 3 PANGURAGAN WETAN | EK13: 282440000 | EL13: =EK13/920000 -> 307 | EM13: =EK13*20% -> 56488000 | EN13: 20215291 | EO13: SD NEGERI 1 CILENGKRANGGIRANG | EP13: 155480000 | EQ13: =EP13/920000 -> 169 | ER13: =EP13*20% -> 31096000 | ES13: 20244368 | ET13: SD NEGERI 1 PANGKALAN | EU13: 195040000 | EV13: =EU13/920000 -> 212 | EW13: =EU13*20% -> 39008000 | EX13: 20244501 | EY13: SD NEGERI 2 KARANGASEM | EZ13: 150880000 | FA13: =EZ13/920000 -> 164 | FB13: =EZ13*20% -> 30176000 | FC13: 20214636 | FD13: SD NEGERI 2 PANAMBANGAN | FE13: 128800000 | FF13: =FE13/920000 -> 140 | FG13: =FE13*20% -> 25760000 | FH13: 20215513 | FI13: SD NEGERI 1 SENDANG | FJ13: 135240000 | FK13: =FJ13/920000 -> 147 | FL13: =FJ13*20% -> 27048000 | FM13: 20214696 | FN13: SD NEGERI 2 SURANENGGALA LOR | FO13: 297160000 | FP13: =FO13/920000 -> 323 | FQ13: =FO13*20% -> 59432000 | FR13: 20215474 | FS13: SD NEGERI 1 TANGKIL | FT13: 276920000 | FU13: =FT13/920000 -> 301 | FV13: =FT13*20% -> 55384000 | FW13: 20215495 | FX13: SD NEGERI 1 PASAWAHAN | FY13: 134320000 | FZ13: =FY13/920000 -> 146 | GA13: =FY13*20% -> 26864000 | GB13: 20215284 | GC13: SD NEGERI 1 CIREBON GIRANG | GD13: 241960000 | GE13: =GD13/920000 -> 263 | GF13: =GD13*20% -> 48392000 | GG13: 20215236 | GH13: SD NEGERI 1 BATEMBAT | GI13: 214360000 | GJ13: =GI13/920000 -> 233 | GK13: =GI13*20% -> 42872000 | GL13: 20214477 | GM13: SD NEGERI 3 CIUYAH | GN13: 164680000 | GO13: =GN13/920000 -> 179 | GP13: =GN13*20% -> 32936000 | GQ13: 20244381 | GR13: SD NEGERI 1 TEGALWANGI | GS13: 200560000 | GT13: =GS13/920000 -> 218 | GU13: =GS13*20% -> 40112000
C14: 10 | D14: 20214737 | E14: SD NEGERI 2 SENDE | F14: 193200000 | G14: =F14/920000 -> 210 | H14: =F14*20% -> 38640000 | I14: 20215048 | J14: SD NEGERI 1 KANCI | K14: 387320000 | L14: =K14/920000 -> 421 | M14: =K14*20% -> 77464000 | N14: 20215533 | O14: SD NEGERI 2 BABAKANGEBANG | P14: 379960000 | Q14: =P14/920000 -> 413 | R14: =P14*20% -> 75992000 | S14: 20215583 | T14: SD NEGERI 1 WANAYASA | U14: 161000000 | V14: =U14/920000 -> 175 | W14: =U14*20% -> 32200000 | X14: 20215353 | Y14: SD NEGERI 2 CILEDUG TENGAH | Z14: 180320000 | AA14: =Z14/920000 -> 196 | AB14: =Z14*20% -> 36064000 | AC14: 20215280 | AD14: SD NEGERI 1 CIWARINGIN | AE14: 494960000 | AF14: =AE14/920000 -> 538 | AG14: =AE14*20% -> 98992000 | AH14: 20214516 | AI14: SD NEGERI 2 WARUROYOM | AJ14: 131560000 | AK14: =AJ14/920000 -> 143 | AL14: =AJ14*20% -> 26312000 | AM14: 20215365 | AN14: SD NEGERI 2 CIPANAS | AO14: 138000000 | AP14: =AO14/920000 -> 150 | AQ14: =AO14*20% -> 27600000 | AR14: 20215369 | AS14: SD NEGERI 2 DOMPYONG WETAN | AT14: 205160000 | AU14: =AT14/920000 -> 223 | AV14: =AT14*20% -> 41032000 | AW14: 20215523 | AX14: SD NEGERI 2 BAYALANGU LOR | AY14: 113160000 | AZ14: =AY14/920000 -> 123 | BA14: =AY14*20% -> 22632000 | BB14: 20215252 | BC14: UPTD NEGERI 1 GEMPOL | BD14: 206080000 | BE14: =BD14/920000 -> 224 | BF14: =BD14*20% -> 41216000 | BG14: 20215083 | BH14: SD NEGERI 1 JATIPANCUR | BI14: 379040000 | BJ14: =BI14/920000 -> 412 | BK14: =BI14*20% -> 75808000 | BL14: 20244364 | BM14: UPTD SD NEGERI 1 MAYUNG | BN14: 437920000 | BO14: =BN14/920000 -> 476 | BP14: =BN14*20% -> 87584000 | BQ14: 20214535 | BR14: SD NEGERI 3 BAKUNGKIDUL | BS14: 143520000 | BT14: =BS14/920000 -> 156 | BU14: =BS14*20% -> 28704000 | BV14: 20215069 | BW14: SD NEGERI 1 KALIWEDI LOR | BX14: 156400000 | BY14: =BX14/920000 -> 170 | BZ14: =BX14*20% -> 31280000 | CA14: 20215040 | CB14: SD NEGERI 1 KARANGKENDAL | CC14: 336720000 | CD14: =CC14/920000 -> 366 | CE14: =CC14*20% -> 67344000 | CF14: 20215016 | CG14: SD NEGERI 3 KALIMEANG | CH14: 71760000 | CI14: =CH14/920000 -> 78 | CJ14: =CH14*20% -> 14352000 | CK14: 20215066 | CL14: SD NEGERI 1 KARANGWANGI | CM14: 417680000 | CN14: =CM14/920000 -> 454 | CO14: =CM14*20% -> 83536000 | CP14: 20215494 | CQ14: SD NEGERI 1 PILANGSARI | CR14: 161000000 | CS14: =CR14/920000 -> 175 | CT14: =CR14*20% -> 32200000 | CU14: 20214738 | CV14: SD NEGERI 2 SERANG | CW14: 108560000 | CX14: =CW14/920000 -> 118 | CY14: =CW14*20% -> 21712000 | CZ14: 20214656 | DA14: SD NEGERI 2 LEMAHABANG | DB14: 357880000 | DC14: =DB14/920000 -> 389 | DD14: =DB14*20% -> 71576000 | DE14: 20215237 | DF14: SD NEGERI 1 BARISAN | DG14: 209760000 | DH14: =DG14/920000 -> 228 | DI14: =DG14*20% -> 41952000 | DJ14: 20215377 | DK14: SD NEGERI 2 CITEMU | DL14: 128800000 | DM14: =DL14/920000 -> 140 | DN14: =DL14*20% -> 25760000 | DO14: 20215087 | DP14: SD NEGERI 1 KALIBUNTU | DQ14: 341320000 | DR14: =DQ14/920000 -> 371 | DS14: =DQ14*20% -> 68264000 | DT14: 20215134 | DU14: SD NEGERI 1 PABUARAN KIDUL | DV14: 573160000 | DW14: =DV14/920000 -> 623 | DX14: =DV14*20% -> 114632000 | DY14: 20214540 | DZ14: SD NEGERI 3 PANONGAN | EA14: 82800000 | EB14: =EA14/920000 -> 90 | EC14: =EA14*20% -> 16560000 | ED14: 20215328 | EE14: SD NEGERI 2 ENDER | EF14: 447120000 | EG14: =EF14/920000 -> 486 | EH14: =EF14*20% -> 89424000 | EI14: 20215124 | EJ14: SD NEGERI 1 PANGURAGAN KULON | EK14: 285200000 | EL14: =EK14/920000 -> 310 | EM14: =EK14*20% -> 57040000 | EN14: 20215199 | EO14: SD NEGERI 1 CIGOBANGWANGI | EP14: 287040000 | EQ14: =EP14/920000 -> 312 | ER14: =EP14*20% -> 57408000 | ES14: 20214941 | ET14: SD NEGERI 3 TEGALSARI | EU14: 152720000 | EV14: =EU14/920000 -> 166 | EW14: =EU14*20% -> 30544000 | EX14: 20214601 | EY14: SD NEGERI 3 LURAH | EZ14: 247480000 | FA14: =EZ14/920000 -> 269 | FB14: =EZ14*20% -> 49496000 | FC14: 20214512 | FD14: SD NEGERI 2 WINDUHAJI | FE14: 122360000 | FF14: =FE14/920000 -> 133 | FG14: =FE14*20% -> 24472000 | FH14: 20215255 | FI14: SD NEGERI 1 GEGUNUNG | FJ14: 462760000 | FK14: =FJ14/920000 -> 503 | FL14: =FJ14*20% -> 92552000 | FM14: 20215394 | FN14: SD NEGERI 2 KARANGREJA | FO14: 119600000 | FP14: =FO14/920000 -> 130 | FQ14: =FO14*20% -> 23920000 | FR14: 20214711 | FS14: SD NEGERI 2 UJUNGGEBANG | FT14: 253920000 | FU14: =FT14/920000 -> 276 | FV14: =FT14*20% -> 50784000 | FW14: 20215295 | FX14: SD NEGERI 1 CURUG | FY14: 276920000 | FZ14: =FY14/920000 -> 301 | GA14: =FY14*20% -> 55384000 | GB14: 20215035 | GC14: SD NEGERI 2 KERANDON | GD14: 188600000 | GE14: =GD14/920000 -> 205 | GF14: =GD14*20% -> 37720000 | GG14: 20215151 | GH14: UPTD SD NEGERI 1 KEMLAKA GEDE | GI14: 341320000 | GJ14: =GI14/920000 -> 371 | GK14: =GI14*20% -> 68264000 | GL14: 20215270 | GM14: SD NEGERI 1 GUNUNGSARI | GN14: 311880000 | GO14: =GN14/920000 -> 339 | GP14: =GN14*20% -> 62376000 | GQ14: 20214948 | GR14: SD NEGERI 4 MEGUGEDE | GS14: 347760000 | GT14: =GS14/920000 -> 378 | GU14: =GS14*20% -> 69552000
C15: 11 | D15: 20215537 | E15: SD NEGERI 2 ARJAWINANGUN | F15: 186760000 | G15: =F15/920000 -> 203 | H15: =F15*20% -> 37352000 | I15: 20214670 | J15: SD NEGERI 2 MUNJUL | K15: 299920000 | L15: =K15/920000 -> 326 | M15: =K15*20% -> 59984000 | N15: 20214519 | O15: SD NEGERI 3 BABAKAN GEBANG | P15: 154560000 | Q15: =P15/920000 -> 168 | R15: =P15*20% -> 30912000 | S15: 20214530 | T15: SD NEGERI 3 BEBER | U15: 237360000 | V15: =U15/920000 -> 258 | W15: =U15*20% -> 47472000 | X15: 20215311 | Y15: SD NEGERI 1 DAMARGUNA | Z15: 218960000 | AA15: =Z15/920000 -> 238 | AB15: =Z15*20% -> 43792000 | AC15: 20244387 | AD15: SD NEGERI 2 BABAKAN | AE15: 136160000 | AF15: =AE15/920000 -> 148 | AG15: =AE15*20% -> 27232000 | AH15: 20244503 | AI15: SD NEGERI 2 KARANGWANGI | AJ15: 242880000 | AK15: =AJ15/920000 -> 264 | AL15: =AJ15*20% -> 48576000 | AM15: 20215116 | AN15: SD NEGERI 1 MANDALA | AO15: 183080000 | AP15: =AO15/920000 -> 199 | AQ15: =AO15*20% -> 36616000 | AR15: 20214485 | AS15: SD NEGERI 3 GEBANG MEKAR | AT15: 263120000 | AU15: =AT15/920000 -> 286 | AV15: =AT15*20% -> 52624000 | AW15: 20215459 | AX15: SD NEGERI 1 SLENDRA | AY15: 103960000 | AZ15: =AY15/920000 -> 113 | BA15: =AY15*20% -> 20792000 | BB15: 20214625 | BC15: SD NEGERI 2 PALIMANAN BARAT | BD15: 362480000 | BE15: =BD15/920000 -> 394 | BF15: =BD15*20% -> 72496000 | BG15: 20215163 | BH15: SD NEGERI 1 LEBAK MEKAR | BI15: 567640000 | BJ15: =BI15/920000 -> 617 | BK15: =BI15*20% -> 113528000 | BL15: 20215085 | BM15: SD NEGERI 1 JATIMERTA | BN15: 148120000 | BO15: =BN15/920000 -> 161 | BP15: =BN15*20% -> 29624000 | BQ15: 20214534 | BR15: SD NEGERI 3 BAKUNGLOR | BS15: 166520000 | BT15: =BS15/920000 -> 181 | BU15: =BS15*20% -> 33304000 | BV15: 20215441 | BW15: SD NEGERI 2 KALIWEDI LOR | BX15: 337640000 | BY15: =BX15/920000 -> 367 | BZ15: =BX15*20% -> 67528000 | CA15: 20215141 | CB15: SD NEGERI 1 KERTASURA | CC15: 230920000 | CD15: =CC15/920000 -> 251 | CE15: =CC15*20% -> 46184000 | CF15: 20215167 | CG15: SD NEGERI 1 KUBANGKARANG | CH15: 196880000 | CI15: =CH15/920000 -> 214 | CJ15: =CH15*20% -> 39376000 | CK15: 20215486 | CL15: SD NEGERI 1 SUMURKONDANG | CM15: 229080000 | CN15: =CM15/920000 -> 249 | CO15: =CM15*20% -> 45816000 | CP15: 20244514 | CQ15: SD NEGERI 1 KALIKOA | CR15: 432400000 | CS15: =CR15/920000 -> 470 | CT15: =CR15*20% -> 86480000 | CU15: 20214661 | CV15: SD NEGERI 2 KREYO | CW15: 139840000 | CX15: =CW15/920000 -> 152 | CY15: =CW15*20% -> 27968000 | CZ15: 20215161 | DA15: SD NEGERI 1 LEMAHABANG KULON | DB15: 207920000 | DC15: =DB15/920000 -> 226 | DD15: =DB15*20% -> 41584000 | DE15: 20215140 | DF15: UPTD SD NEGERI 1 LOSARI KIDUL | DG15: 328440000 | DH15: =DG15/920000 -> 357 | DI15: =DG15*20% -> 65688000 | DJ15: 20214580 | DK15: SD NEGERI 3 PENPEN | DL15: 223560000 | DM15: =DL15/920000 -> 243 | DN15: =DL15*20% -> 44712000 | DO15: 20214631 | DP15: SD NEGERI 2 PABEDILAN KIDUL | DQ15: 185840000 | DR15: =DQ15/920000 -> 202 | DS15: =DQ15*20% -> 37168000 | DT15: 20214549 | DU15: SD NEGERI 3 PABUARAN WETAN | DV15: 281520000 | DW15: =DV15/920000 -> 306 | DX15: =DV15*20% -> 56304000 | DY15: 20214544 | DZ15: SD NEGERI 3 PALIMANAN TIMUR | EA15: 214360000 | EB15: =EA15/920000 -> 233 | EC15: =EA15*20% -> 42872000 | ED15: 20214913 | EE15: SD NEGERI 1 BENDUNGAN | EF15: 249320000 | EG15: =EF15/920000 -> 271 | EH15: =EF15*20% -> 49864000 | EI15: 20215160 | EJ15: SD NEGERI 1 LEMAHTAMBA | EK15: 200560000 | EL15: =EK15/920000 -> 218 | EM15: =EK15*20% -> 40112000 | EN15: 20215292 | EO15: SD NEGERI 1 CILENGKRANG | EP15: 143520000 | EQ15: =EP15/920000 -> 156 | ER15: =EP15*20% -> 28704000 | ES15: 20215440 | ET15: SD NEGERI 2 KALIWULU | EU15: 386400000 | EV15: =EU15/920000 -> 420 | EW15: =EU15*20% -> 77280000 | EX15: 20215190 | EY15: SD NEGERI 1 BODESARI | EZ15: 165600000 | FA15: =EZ15/920000 -> 180 | FB15: =EZ15*20% -> 33120000 | FC15: 20214724 | FD15: SD NEGERI 2 SEDONG KIDUL | FE15: 178480000 | FF15: =FE15/920000 -> 194 | FG15: =FE15*20% -> 35696000 | FH15: 20214722 | FI15: SD NEGERI 2 SENDANG | FJ15: 240120000 | FK15: =FJ15/920000 -> 261 | FL15: =FJ15*20% -> 48024000 | FM15: 20214672 | FN15: SD NEGERI 2 MUARA | FO15: 232760000 | FP15: =FO15/920000 -> 253 | FQ15: =FO15*20% -> 46552000 | FR15: 20214600 | FS15: SD NEGERI 3 LUWUNG KENCANA | FT15: 118680000 | FU15: =FT15/920000 -> 129 | FV15: =FT15*20% -> 23736000 | FW15: 20215204 | FX15: SD NEGERI 1 CIAWIASIH | FY15: 222640000 | FZ15: =FY15/920000 -> 242 | GA15: =FY15*20% -> 44528000 | GB15: 20214706 | GC15: SD NEGERI 2 WANASABA KIDUL | GD15: 224480000 | GE15: =GD15/920000 -> 244 | GF15: =GD15*20% -> 44896000 | GG15: 20214470 | GH15: SD NEGERI 3 DAWUAN | GI15: 403880000 | GJ15: =GI15/920000 -> 439 | GK15: =GI15*20% -> 80776000 | GL15: 20254084 | GM15: SD NEGERI 1 CISAAT | GN15: 239200000 | GO15: =GN15/920000 -> 260 | GP15: =GN15*20% -> 47840000 | GQ15: 20214751 | GR15: SD NEGERI 2 SETU WETAN BANK JABAR | GS15: 379960000 | GT15: =GS15/920000 -> 413 | GU15: =GS15*20% -> 75992000
